Workbook
Name Indicadores20251211131219: ORG!$A$1:$AI$411
Name Indicadores20251211133442: DES!$A$1:$AH$411
Name Indicadores20251211161923: TEND!$A$1:$AH$411

Sheet ORG
A1: National Institute of Statistics and Geography (INEGI)
A2: Economic Information Bank
A3: Consult Date: 13/03/2026 07:30:50
A4: Índice base 2018=100
A6: Period | B6: Geographic area | C6: Indicadores económicos de coyuntura > Actividad industrial, base 2018 > Series Originales > Índice de volumen físico > Total de la actividad industrial (Índice base 2018=100) Monthly /f1 | D6: Indicadores económicos de coyuntura > Actividad industrial, base 2018 > Series Originales > Índice de volumen físico > 21 Minería > Total minería (Índice base 2018=100) Monthly /f1 | E6: Indicadores económicos de coyuntura > Actividad industrial, base 2018 > Series Originales > Índice de volumen físico > 21 Minería > 211 Extracción de petróleo y gas (Índice base 2018=100) Monthly /f1 | F6: Indicadores económicos de coyuntura > Actividad industrial, base 2018 > Series Originales > Índice de volumen físico > 21 Minería > 212 Minería de minerales metálicos y no metálicos excepto petróleo y gas (Índice base 2018=100) Monthly /f1 | G6: Indicadores económicos de coyuntura > Actividad industrial, base 2018 > Series Originales > Índice de volumen físico > 21 Minería > 213 Servicios relacionados con la minería (Índice base 2018=100) Monthly /f1 | H6: Indicadores económicos de coyuntura > Actividad industrial, base 2018 > Series Originales > Índice de volumen físico > 22 Generación, transmisión y distribución de energía eléctrica, suministro de agua y de gas por ductos al consumidor final > Total generación, transmisión y distribución de energía eléctrica, suministro de agua y de gas por ductos al consumidor final (Índice base 2018=100) Monthly /f1 | I6: Indicadores económicos de coyuntura > Actividad industrial, base 2018 > Series Originales > Índice de volumen físico > 22 Generación, transmisión y distribución de energía eléctrica, suministro de agua y de gas por ductos al consumidor final > 221 Generación, transmisión, distribución y comercialización de energía eléctrica, suministro de agua y de gas natural por ductos al consumidor final (Índice base 2018=100) Monthly /f1 | J6: Indicadores económicos de coyuntura > Actividad industrial, base 2018 > Series Originales > Índice de volumen físico > 23 Construcción > Total construcción (Índice base 2018=100) Monthly /f1 | K6: Indicadores económicos de coyuntura > Actividad industrial, base 2018 > Series Originales > Índice de volumen físico > 23 Construcción > 236 Edificación (Índice base 2018=100) Monthly /f1 | L6: Indicadores económicos de coyuntura > Actividad industrial, base 2018 > Series Originales > Índice de volumen físico > 23 Construcción > 237 Construcción de obras de ingeniería civil (Índice base 2018=100) Monthly /f1 | M6: Indicadores económicos de coyuntura > Actividad industrial, base 2018 > Series Originales > Índice de volumen físico > 23 Construcción > 238 Trabajos especializados para la construcción (Índice base 2018=100) Monthly /f1 | N6: Indicadores económicos de coyuntura > Actividad industrial, base 2018 > Series Originales > Índice de volumen físico > 31-33 Industrias manufactureras > Total industrias manufactureras (Índice base 2018=100) Monthly /f1 | O6: Indicadores económicos de coyuntura > Actividad industrial, base 2018 > Series Originales > Índice de volumen físico > 31-33 Industrias manufactureras > 311 Industria alimentaria > Total subsector 311 (Índice base 2018=100) Monthly /f1 | P6: Indicadores económicos de coyuntura > Actividad industrial, base 2018 > Series Originales > Índice de volumen físico > 31-33 Industrias manufactureras > 312 Industria de las bebidas y del tabaco > Total subsector 312 (Índice base 2018=100) Monthly /f1 | Q6: Indicadores económicos de coyuntura > Actividad industrial, base 2018 > Series Originales > Índice de volumen físico > 31-33 Industrias manufactureras > 313 Fabricación de insumos textiles y acabado de textiles > Total subsector 313 (Índice base 2018=100) Monthly /f1 | R6: Indicadores económicos de coyuntura > Actividad industrial, base 2018 > Series Originales > Índice de volumen físico > 31-33 Industrias manufactureras > 314 Fabricación de productos textiles, excepto prendas de vestir > Total subsector 314 (Índice base 2018=100) Monthly /f1 | S6: Indicadores económicos de coyuntura > Actividad industrial, base 2018 > Series Originales > Índice de volumen físico > 31-33 Industrias manufactureras > 315 Fabricación de prendas de vestir > Total subsector 315 (Índice base 2018=100) Monthly /f1 | T6: Indicadores económicos de coyuntura > Actividad industrial, base 2018 > Series Originales > Índice de volumen físico > 31-33 Industrias manufactureras > 316 Curtido y acabado de cuero y piel, y fabricación de productos de cuero, piel y materiales sucedáneos > Total subsector 316 (Índice base 2018=100) Monthly /f1 | U6: Indicadores económicos de coyuntura > Actividad industrial, base 2018 > Series Originales > Índice de volumen físico > 31-33 Industrias manufactureras > 321 Industria de la madera > Total subsector 321 (Índice base 2018=100) Monthly /f1 | V6: Indicadores económicos de coyuntura > Actividad industrial, base 2018 > Series Originales > Índice de volumen físico > 31-33 Industrias manufactureras > 322 Industria del papel > Total subsector 322 (Índice base 2018=100) Monthly /f1 | W6: Indicadores económicos de coyuntura > Actividad industrial, base 2018 > Series Originales > Índice de volumen físico > 31-33 Industrias manufactureras > 323 Impresión e industrias conexas > Total subsector 323 (Índice base 2018=100) Monthly /f1 | X6: Indicadores económicos de coyuntura > Actividad industrial, base 2018 > Series Originales > Índice de volumen físico > 31-33 Industrias manufactureras > 324 Fabricación de productos derivados del petróleo y del carbón > Total subsector 324 (Índice base 2018=100) Monthly /f1 | Y6: Indicadores económicos de coyuntura > Actividad industrial, base 2018 > Series Originales > Índice de volumen físico > 31-33 Industrias manufactureras > 325 Industria química > Total subsector 325 (Índice base 2018=100) Monthly /f1 | Z6: Indicadores económicos de coyuntura > Actividad industrial, base 2018 > Series Originales > Índice de volumen físico > 31-33 Industrias manufactureras > 326 Industria del plástico y del hule > Total subsector 326 (Índice base 2018=100) Monthly /f1 | AA6: Indicadores económicos de coyuntura > Actividad industrial, base 2018 > Series Originales > Índice de volumen físico > 31-33 Industrias manufactureras > 327 Fabricación de productos a base de minerales no metálicos > Total subsector 327 (Índice base 2018=100) Monthly /f1 | AB6: Indicadores económicos de coyuntura > Actividad industrial, base 2018 > Series Originales > Índice de volumen físico > 31-33 Industrias manufactureras > 331 Industrias metálicas básicas > Total subsector 331 (Índice base 2018=100) Monthly /f1 | AC6: Indicadores económicos de coyuntura > Actividad industrial, base 2018 > Series Originales > Índice de volumen físico > 31-33 Industrias manufactureras > 332 Fabricación de productos metálicos > Total subsector 332 (Índice base 2018=100) Monthly /f1 | AD6: Indicadores económicos de coyuntura > Actividad industrial, base 2018 > Series Originales > Índice de volumen físico > 31-33 Industrias manufactureras > 333 Fabricación de maquinaria y equipo > Total subsector 333 (Índice base 2018=100) Monthly /f1 | AE6: Indicadores económicos de coyuntura > Actividad industrial, base 2018 > Series Originales > Índice de volumen físico > 31-33 Industrias manufactureras > 334 Fabricación de equipo de computación, comunicación, medición y de otros equipos, componentes y accesorios electrónicos > Total subsector 334 (Índice base 2018=100) Monthly /f1 | AF6: Indicadores económicos de coyuntura > Actividad industrial, base 2018 > Series Originales > Índice de volumen físico > 31-33 Industrias manufactureras > 335 Fabricación de accesorios, aparatos eléctricos y equipo de generación de energía eléctrica > Total subsector 335 (Índice base 2018=100) Monthly /f1 | AG6: Indicadores económicos de coyuntura > Actividad industrial, base 2018 > Series Originales > Índice de volumen físico > 31-33 Industrias manufactureras > 336 Fabricación de equipo de transporte > Total subsector 336 (Índice base 2018=100) Monthly /f1 | AH6: Indicadores económicos de coyuntura > Actividad industrial, base 2018 > Series Originales > Índice de volumen físico > 31-33 Industrias manufactureras > 337 Fabricación de muebles, colchones y persianas > Total subsector 337 (Índice base 2018=100) Monthly /f1 | AI6: Indicadores económicos de coyuntura > Actividad industrial, base 2018 > Series Originales > Índice de volumen físico > 31-33 Industrias manufactureras > 339 Otras industrias manufactureras > Total subsector 339 (Índice base 2018=100) Monthly /f1
A7: 1993/01 | B7: 00 Estados Unidos Mexicanos | C7: 63.307782 | D7: 105.63372 | E7: 137.51945 | F7: 51.030422 | G7: 19.03529 | H7: 31.140234 | I7: 31.140234 | J7: 65.066709 | K7: 70.822977 | L7: 47.897351 | M7: 51.564633 | N7: 57.569208 | O7: 57.390254 | P7: 44.153444 | Q7: 94.833067 | R7: 62.183341 | S7: 68.45063 | T7: 145.51019 | U7: 116.59941 | V7: 43.682621 | W7: 51.19384 | X7: 148.67981 | Y7: 74.371783 | Z7: 55.01086 | AA7: 61.979202 | AB7: 64.278668 | AC7: 68.80715 | AD7: 92.173815 | AE7: 63.077464 | AF7: 89.356525 | AG7: 22.932642 | AH7: 102.71802 | AI7: 25.311203
A8: 1993/02 | B8: 00 Estados Unidos Mexicanos | C8: 64.88913 | D8: 97.271624 | E8: 124.34812 | F8: 50.893698 | G8: 23.778913 | H8: 30.534604 | I8: 30.534604 | J8: 72.301502 | K8: 81.527051 | L8: 43.250169 | M8: 52.468069 | N8: 59.595205 | O8: 56.498795 | P8: 44.012904 | Q8: 104.82684 | R8: 68.950249 | S8: 74.73758 | T8: 134.21673 | U8: 149.07586 | V8: 42.906637 | W8: 61.957641 | X8: 136.84145 | Y8: 75.260068 | Z8: 61.863461 | AA8: 61.588003 | AB8: 62.448839 | AC8: 74.174943 | AD8: 76.252788 | AE8: 67.30135 | AF8: 132.28874 | AG8: 25.583303 | AH8: 85.137909 | AI8: 31.087167
A9: 1993/03 | B9: 00 Estados Unidos Mexicanos | C9: 68.070475 | D9: 109.36336 | E9: 138.97018 | F9: 58.169826 | G9: 31.07088 | H9: 30.87515 | I9: 30.87515 | J9: 72.200179 | K9: 79.128218 | L9: 52.883713 | M9: 54.362407 | N9: 62.29373 | O9: 63.501836 | P9: 48.047544 | Q9: 120.93757 | R9: 83.426598 | S9: 92.182461 | T9: 130.05973 | U9: 150.27262 | V9: 48.080186 | W9: 78.512853 | X9: 152.64309 | Y9: 84.862447 | Z9: 63.356535 | AA9: 69.985766 | AB9: 79.890169 | AC9: 74.734566 | AD9: 68.95213 | AE9: 44.941939 | AF9: 102.19225 | AG9: 29.505776 | AH9: 95.998047 | AI9: 43.612944
A10: 1993/04 | B10: 00 Estados Unidos Mexicanos | C10: 64.524614 | D10: 105.54602 | E10: 136.19254 | F10: 52.224819 | G10: 25.920872 | H10: 31.478529 | I10: 31.478529 | J10: 65.190467 | K10: 72.387479 | L10: 43.424498 | M10: 48.661319 | N10: 59.448857 | O10: 58.744075 | P10: 44.859164 | Q10: 94.519973 | R10: 76.133837 | S10: 82.431411 | T10: 119.61867 | U10: 106.7142 | V10: 45.623729 | W10: 48.44936 | X10: 151.07931 | Y10: 72.737881 | Z10: 61.153979 | AA10: 63.875252 | AB10: 75.151028 | AC10: 56.992991 | AD10: 57.119224 | AE10: 84.844837 | AF10: 86.734528 | AG10: 25.439879 | AH10: 84.081552 | AI10: 46.197448
A11: 1993/05 | B11: 00 Estados Unidos Mexicanos | C11: 64.382808 | D11: 108.37189 | E11: 141.07461 | F11: 51.39583 | G11: 23.7365 | H11: 32.421097 | I11: 32.421097 | J11: 65.265742 | K11: 70.539985 | L11: 47.224884 | M11: 55.613344 | N11: 58.564004 | O11: 56.901305 | P11: 52.096605 | Q11: 113.49406 | R11: 78.465527 | S11: 83.241648 | T11: 131.23378 | U11: 99.867458 | V11: 46.510548 | W11: 59.980155 | X11: 145.1001 | Y11: 84.723354 | Z11: 54.93035 | AA11: 70.553806 | AB11: 68.741554 | AC11: 57.673804 | AD11: 103.75202 | AE11: 60.98201 | AF11: 55.468076 | AG11: 25.483181 | AH11: 87.462363 | AI11: 30.722828
A12: 1993/06 | B12: 00 Estados Unidos Mexicanos | C12: 62.471146 | D12: 104.86255 | E12: 136.55268 | F12: 48.681739 | G12: 27.009119 | H12: 32.308556 | I12: 32.308556 | J12: 64.263124 | K12: 68.29113 | L12: 50.337472 | M12: 57.06529 | N12: 56.522282 | O12: 54.479365 | P12: 44.861248 | Q12: 128.20666 | R12: 90.264204 | S12: 86.187053 | T12: 125.88838 | U12: 114.52614 | V12: 44.46658 | W12: 62.491634 | X12: 150.91294 | Y12: 87.218856 | Z12: 50.713867 | AA12: 67.682672 | AB12: 62.6407 | AC12: 63.757022 | AD12: 80.869801 | AE12: 50.623456 | AF12: 80.277759 | AG12: 23.229154 | AH12: 84.240608 | AI12: 30.793396
A13: 1993/07 | B13: 00 Estados Unidos Mexicanos | C13: 64.791953 | D13: 108.4778 | E13: 139.30101 | F13: 53.147382 | G13: 35.702534 | H13: 32.780141 | I13: 32.780141 | J13: 65.932771 | K13: 69.72745 | L13: 56.998255 | M13: 54.224863 | N13: 58.959575 | O13: 54.092809 | P13: 44.997517 | Q13: 107.43628 | R13: 81.384212 | S13: 81.163123 | T13: 128.20263 | U13: 77.156215 | V13: 46.533101 | W13: 72.753131 | X13: 148.23282 | Y13: 78.332105 | Z13: 48.137441 | AA13: 65.989923 | AB13: 66.24088 | AC13: 55.592486 | AD13: 117.43974 | AE13: 84.734295 | AF13: 74.921658 | AG13: 20.990239 | AH13: 94.494641 | AI13: 34.230792
A14: 1993/08 | B14: 00 Estados Unidos Mexicanos | C14: 66.301834 | D14: 107.44436 | E14: 138.94431 | F14: 53.568312 | G14: 21.607658 | H14: 32.121464 | I14: 32.121464 | J14: 73.735953 | K14: 79.685283 | L14: 54.112194 | M14: 61.992936 | N14: 59.283157 | O14: 54.022773 | P14: 42.171006 | Q14: 97.491887 | R14: 95.871069 | S14: 84.921394 | T14: 128.28999 | U14: 82.074308 | V14: 43.521364 | W14: 99.495514 | X14: 159.52989 | Y14: 80.502281 | Z14: 52.799026 | AA14: 65.497135 | AB14: 63.135708 | AC14: 83.855074 | AD14: 82.661925 | AE14: 74.849598 | AF14: 106.5077 | AG14: 20.724113 | AH14: 92.178936 | AI14: 37.246239
A15: 1993/09 | B15: 00 Estados Unidos Mexicanos | C15: 67.703709 | D15: 105.4224 | E15: 136.74228 | F15: 51.065528 | G15: 23.464133 | H15: 32.169525 | I15: 32.169525 | J15: 76.459477 | K15: 80.522312 | L15: 64.86204 | M15: 66.316263 | N15: 61.081424 | O15: 55.097998 | P15: 41.091602 | Q15: 99.243382 | R15: 94.183051 | S15: 84.223276 | T15: 126.19483 | U15: 89.621461 | V15: 43.229357 | W15: 80.736709 | X15: 160.49837 | Y15: 82.278088 | Z15: 55.440858 | AA15: 64.826524 | AB15: 70.422934 | AC15: 67.144042 | AD15: 51.755421 | AE15: 71.920327 | AF15: 179.28168 | AG15: 22.636358 | AH15: 91.307875 | AI15: 42.537639
A16: 1993/10 | B16: 00 Estados Unidos Mexicanos | C16: 66.405456 | D16: 110.53434 | E16: 142.33441 | F16: 55.971487 | G16: 24.624958 | H16: 30.805084 | I16: 30.805084 | J16: 73.707244 | K16: 75.875909 | L16: 75.677492 | M16: 58.684111 | N16: 58.979102 | O16: 55.919523 | P16: 43.460296 | Q16: 111.16329 | R16: 94.695413 | S16: 83.100261 | T16: 144.40548 | U16: 78.975013 | V16: 43.801391 | W16: 78.517026 | X16: 159.04334 | Y16: 86.327758 | Z16: 69.344234 | AA16: 68.118117 | AB16: 69.432957 | AC16: 68.171427 | AD16: 75.367304 | AE16: 47.358398 | AF16: 106.38905 | AG16: 25.621235 | AH16: 66.859023 | AI16: 44.057522
A17: 1993/11 | B17: 00 Estados Unidos Mexicanos | C17: 65.323065 | D17: 107.19305 | E17: 137.67783 | F17: 54.383918 | G17: 26.997568 | H17: 29.53864 | I17: 29.53864 | J17: 72.199083 | K17: 72.181391 | L17: 85.633097 | M17: 56.484827 | N17: 58.480231 | O17: 53.864974 | P17: 46.508783 | Q17: 104.44186 | R17: 66.0694 | S17: 99.34826 | T17: 135.75556 | U17: 78.018508 | V17: 42.093758 | W17: 97.991035 | X17: 150.11475 | Y17: 86.981682 | Z17: 52.020437 | AA17: 64.733273 | AB17: 65.661812 | AC17: 74.363642 | AD17: 56.761817 | AE17: 84.158652 | AF17: 61.25698 | AG17: 25.057148 | AH17: 81.880953 | AI17: 38.668976
A18: 1993/12 | B18: 00 Estados Unidos Mexicanos | C18: 67.828452 | D18: 111.2314 | E18: 142.64912 | F18: 53.492815 | G18: 42.811629 | H18: 28.360196 | I18: 28.360196 | J18: 79.241961 | K18: 80.071807 | L18: 85.913968 | M18: 66.525065 | N18: 59.674666 | O18: 62.389871 | P18: 60.152075 | Q18: 95.296548 | R18: 73.856474 | S18: 73.451446 | T18: 109.31282 | U18: 112.55095 | V18: 38.938847 | W18: 99.534732 | X18: 162.63747 | Y18: 76.032291 | Z18: 52.525657 | AA18: 64.195783 | AB18: 63.391228 | AC18: 50.162514 | AD18: 50.760867 | AE18: 83.841417 | AF18: 96.624942 | AG18: 24.104653 | AH18: 97.084399 | AI18: 27.085022
... A403: 2026/01 | B403: 00 Estados Unidos Mexicanos | C403: 96.708135 | D403: 90.606131 | E403: 92.135223 | F403: 86.100506 | G403: 94.557987 | H403: 60.872605 | I403: 60.872605 | J403: 98.368072 | K403: 97.146075 | L403: 96.423119 | M403: 107.81617 | N403: 100.75135 | O403: 110.71842 | P403: 97.514088 | Q403: 68.537279 | R403: 78.451087 | S403: 62.617626 | T403: 69.00247 | U403: 75.884118 | V403: 97.238908 | W403: 91.31173 | X403: 160.0807 | Y403: 97.5325 | Z403: 100.02994 | AA403: 96.363275 | AB403: 95.888538 | AC403: 88.36789 | AD403: 100.91147 | AE403: 112.0744 | AF403: 109.90919 | AG403: 88.36518 | AH403: 82.519592 | AI403: 124.32227
A408: Sources: /f1 INEGI System of National Accounts of Mexico. Monthly Industrial Activity Indicator (IMAI)

Sheet DES
A1: National Institute of Statistics and Geography (INEGI)
A2: Economic Information Bank
A3: Consult Date: 13/03/2026 07:31:09
A4: Índice base 2018=100
A6: Period | B6: Geographic area | C6: Indicadores económicos de coyuntura > Actividad industrial, base 2018 > Series desestacionalizadas y tendencia-ciclo > Total de la actividad industrial > Serie desestacionalizada > Índice (Índice base 2018=100) Monthly /f1 | D6: Indicadores económicos de coyuntura > Actividad industrial, base 2018 > Series desestacionalizadas y tendencia-ciclo > Minería > Total > Serie desestacionalizada > Índice (Índice base 2018=100) Monthly /f1 | E6: Indicadores económicos de coyuntura > Actividad industrial, base 2018 > Series desestacionalizadas y tendencia-ciclo > Minería > 211 Extracción de petróleo y gas > Serie desestacionalizada > Índice (Índice base 2018=100) Monthly /f1 | F6: Indicadores económicos de coyuntura > Actividad industrial, base 2018 > Series desestacionalizadas y tendencia-ciclo > Minería > 212 Minería de minerales metálicos y no metálicos, excepto petróleo y gas > Serie desestacionalizada > Índice (Índice base 2018=100) Monthly /f1 | G6: Indicadores económicos de coyuntura > Actividad industrial, base 2018 > Series desestacionalizadas y tendencia-ciclo > Minería > 213 Servicios relacionados con la minería > Serie desestacionalizada > Índice (Índice base 2018=100) Monthly /f1 | H6: Indicadores económicos de coyuntura > Actividad industrial, base 2018 > Series desestacionalizadas y tendencia-ciclo > Generación, transmisión y distribución de energía eléctrica, suministro de agua y de gas por ductos al consumidor final > Serie desestacionalizada > Índice (Índice base 2018=100) Monthly /f1 | I6: Indicadores económicos de coyuntura > Actividad industrial, base 2018 > Series desestacionalizadas y tendencia-ciclo > Construcción > Total > Serie desestacionalizada > Índice (Índice base 2018=100) Monthly /f1 | J6: Indicadores económicos de coyuntura > Actividad industrial, base 2018 > Series desestacionalizadas y tendencia-ciclo > Construcción > 236 Edificación > Serie desestacionalizada > Índice (Índice base 2018=100) Monthly /f1 | K6: Indicadores económicos de coyuntura > Actividad industrial, base 2018 > Series desestacionalizadas y tendencia-ciclo > Construcción > 237 Construcción de obras de ingeniería civil > Serie desestacionalizada > Índice (Índice base 2018=100) Monthly /f1 | L6: Indicadores económicos de coyuntura > Actividad industrial, base 2018 > Series desestacionalizadas y tendencia-ciclo > Construcción > 238 Trabajos especializados para la construcción > Serie desestacionalizada > Índice (Índice base 2018=100) Monthly /f1 | M6: Indicadores económicos de coyuntura > Actividad industrial, base 2018 > Series desestacionalizadas y tendencia-ciclo > Industrias manufactureras > Total > Serie desestacionalizada > Índice (Índice base 2018=100) Monthly /f1 | N6: Indicadores económicos de coyuntura > Actividad industrial, base 2018 > Series desestacionalizadas y tendencia-ciclo > Industrias manufactureras > 311 Industria alimentaria > Serie desestacionalizada > Índice (Índice base 2018=100) Monthly /f1 | O6: Indicadores económicos de coyuntura > Actividad industrial, base 2018 > Series desestacionalizadas y tendencia-ciclo > Industrias manufactureras > 312 Industria de las bebidas y del tabaco > Serie desestacionalizada > Índice (Índice base 2018=100) Monthly /f1 | P6: Indicadores económicos de coyuntura > Actividad industrial, base 2018 > Series desestacionalizadas y tendencia-ciclo > Industrias manufactureras > 313 Fabricación de insumos textiles y acabado de textiles > Serie desestacionalizada > Índice (Índice base 2018=100) Monthly /f1 | Q6: Indicadores económicos de coyuntura > Actividad industrial, base 2018 > Series desestacionalizadas y tendencia-ciclo > Industrias manufactureras > 314 Fabricación de productos textiles, excepto prendas de vestir > Serie desestacionalizada > Índice (Índice base 2018=100) Monthly /f1 | R6: Indicadores económicos de coyuntura > Actividad industrial, base 2018 > Series desestacionalizadas y tendencia-ciclo > Industrias manufactureras > 315 Fabricación de prendas de vestir > Serie desestacionalizada > Índice (Índice base 2018=100) Monthly /f1 | S6: Indicadores económicos de coyuntura > Actividad industrial, base 2018 > Series desestacionalizadas y tendencia-ciclo > Industrias manufactureras > 316 Curtido y acabado de cuero y piel, y fabricación de productos de cuero, piel y materiales sucedáneos > Serie desestacionalizada > Índice (Índice base 2018=100) Monthly /f1 | T6: Indicadores económicos de coyuntura > Actividad industrial, base 2018 > Series desestacionalizadas y tendencia-ciclo > Industrias manufactureras > 321 Industria de la madera > Serie desestacionalizada > Índice (Índice base 2018=100) Monthly /f1 | U6: Indicadores económicos de coyuntura > Actividad industrial, base 2018 > Series desestacionalizadas y tendencia-ciclo > Industrias manufactureras > 322 Industria del papel > Serie desestacionalizada > Índice (Índice base 2018=100) Monthly /f1 | V6: Indicadores económicos de coyuntura > Actividad industrial, base 2018 > Series desestacionalizadas y tendencia-ciclo > Industrias manufactureras > 323 Impresión e industrias conexas > Serie desestacionalizada > Índice (Índice base 2018=100) Monthly /f1 | W6: Indicadores económicos de coyuntura > Actividad industrial, base 2018 > Series desestacionalizadas y tendencia-ciclo > Industrias manufactureras > 324 Fabricación de productos derivados del petróleo y del carbón > Serie desestacionalizada > Índice (Índice base 2018=100) Monthly /f1 | X6: Indicadores económicos de coyuntura > Actividad industrial, base 2018 > Series desestacionalizadas y tendencia-ciclo > Industrias manufactureras > 325 Industria química > Serie desestacionalizada > Índice (Índice base 2018=100) Monthly /f1 | Y6: Indicadores económicos de coyuntura > Actividad industrial, base 2018 > Series desestacionalizadas y tendencia-ciclo > Industrias manufactureras > 326 Industria del plástico y del hule > Serie desestacionalizada > Índice (Índice base 2018=100) Monthly /f1 | Z6: Indicadores económicos de coyuntura > Actividad industrial, base 2018 > Series desestacionalizadas y tendencia-ciclo > Industrias manufactureras > 327 Fabricación de productos a base de minerales no metálicos > Serie desestacionalizada > Índice (Índice base 2018=100) Monthly /f1 | AA6: Indicadores económicos de coyuntura > Actividad industrial, base 2018 > Series desestacionalizadas y tendencia-ciclo > Industrias manufactureras > 331 Industrias metálicas básicas > Serie desestacionalizada > Índice (Índice base 2018=100) Monthly /f1 | AB6: Indicadores económicos de coyuntura > Actividad industrial, base 2018 > Series desestacionalizadas y tendencia-ciclo > Industrias manufactureras > 332 Fabricación de productos metálicos > Serie desestacionalizada > Índice (Índice base 2018=100) Monthly /f1 | AC6: Indicadores económicos de coyuntura > Actividad industrial, base 2018 > Series desestacionalizadas y tendencia-ciclo > Industrias manufactureras > 333 Fabricación de maquinaria y equipo > Serie desestacionalizada > Índice (Índice base 2018=100) Monthly /f1 | AD6: Indicadores económicos de coyuntura > Actividad industrial, base 2018 > Series desestacionalizadas y tendencia-ciclo > Industrias manufactureras > 334 Fabricación de equipo de computación, comunicación, medición y de otros equipos, componentes y accesorios electrónicos > Serie desestacionalizada > Índice (Índice base 2018=100) Monthly /f1 | AE6: Indicadores económicos de coyuntura > Actividad industrial, base 2018 > Series desestacionalizadas y tendencia-ciclo > Industrias manufactureras > 335 Fabricación de accesorios, aparatos eléctricos y equipo de generación de energía eléctrica > Serie desestacionalizada > Índice (Índice base 2018=100) Monthly /f1 | AF6: Indicadores económicos de coyuntura > Actividad industrial, base 2018 > Series desestacionalizadas y tendencia-ciclo > Industrias manufactureras > 336 Fabricación de equipo de transporte > Serie desestacionalizada > Índice (Índice base 2018=100) Monthly /f1 | AG6: Indicadores económicos de coyuntura > Actividad industrial, base 2018 > Series desestacionalizadas y tendencia-ciclo > Industrias manufactureras > 337 Fabricación de muebles, colchones y persianas > Serie desestacionalizada > Índice (Índice base 2018=100) Monthly /f1 | AH6: Indicadores económicos de coyuntura > Actividad industrial, base 2018 > Series desestacionalizadas y tendencia-ciclo > Industrias manufactureras > 339 Otras industrias manufactureras > Serie desestacionalizada > Índice (Índice base 2018=100) Monthly /f1
A7: 1993/01 | B7: 00 Estados Unidos Mexicanos | C7: 63.26103 | D7: 103.82647 | E7: 133.98785 | F7: 51.489374 | G7: 26.854341 | H7: 32.320958 | I7: 68.087611 | J7: 73.536747 | K7: 50.697415 | L7: 54.833964 | M7: 56.77008 | N7: 56.780537 | O7: 46.366794 | P7: 103.38708 | Q7: 79.88106 | R7: 84.733854 | S7: 135.26278 | T7: 119.03441 | U7: 43.472387 | V7: 69.432047 | W7: 145.44612 | X7: 78.872198 | Y7: 56.392929 | Z7: 65.276482 | AA7: 67.314687 | AB7: 65.551741 | AC7: 90.911166 | AD7: 50.931974 | AE7: 76.333205 | AF7: 24.177137 | AG7: 88.090134 | AH7: 32.112855
A8: 1993/02 | B8: 00 Estados Unidos Mexicanos | C8: 65.757306 | D8: 104.84791 | E8: 135.25618 | F8: 53.937731 | G8: 25.957183 | H8: 32.337334 | I8: 70.051908 | J8: 74.834097 | K8: 53.961727 | L8: 56.177349 | M8: 59.072325 | N8: 56.221835 | O8: 48.176568 | P8: 106.75576 | Q8: 83.847721 | R8: 84.040329 | S8: 132.42429 | T8: 126.78732 | U8: 45.267828 | V8: 78.619132 | W8: 147.70218 | X8: 81.404746 | Y8: 57.026337 | Z8: 66.914486 | AA8: 64.742894 | AB8: 66.815088 | AC8: 56.643141 | AD8: 62.768641 | AE8: 122.42896 | AF8: 26.81333 | AG8: 90.481818 | AH8: 35.097325
A9: 1993/03 | B9: 00 Estados Unidos Mexicanos | C9: 66.222786 | D9: 106.02794 | E9: 136.23164 | F9: 54.334335 | G9: 26.028827 | H9: 32.150385 | I9: 70.198768 | J9: 75.630133 | K9: 54.425708 | L9: 56.302664 | M9: 59.774 | N9: 57.07768 | O9: 47.444381 | P9: 111.19445 | Q9: 81.676924 | R9: 86.209094 | S9: 125.95182 | T9: 123.99606 | U9: 45.705775 | V9: 78.057279 | W9: 143.50682 | X9: 82.263871 | Y9: 56.334312 | Z9: 67.545384 | AA9: 70.697408 | AB9: 71.651247 | AC9: 71.655325 | AD9: 61.729397 | AE9: 119.74935 | AF9: 27.769934 | AG9: 95.892594 | AH9: 35.461998
A10: 1993/04 | B10: 00 Estados Unidos Mexicanos | C10: 65.399307 | D10: 106.6871 | E10: 137.68517 | F10: 52.68964 | G10: 25.433014 | H10: 32.249054 | I10: 69.636469 | J10: 75.294289 | K10: 49.484792 | L10: 55.446831 | M10: 59.205722 | N10: 55.576302 | O10: 48.299643 | P10: 107.72247 | Q10: 81.152939 | R10: 83.468886 | S10: 130.27991 | T10: 109.30413 | U10: 45.682787 | V10: 76.228461 | W10: 148.43366 | X10: 76.013326 | Y10: 55.706286 | Z10: 67.331203 | AA10: 70.307539 | AB10: 63.446402 | AC10: 69.901435 | AD10: 86.238234 | AE10: 80.404952 | AF10: 25.9339 | AG10: 92.370344 | AH10: 44.093886
A11: 1993/05 | B11: 00 Estados Unidos Mexicanos | C11: 65.404542 | D11: 106.17935 | E11: 137.81919 | F11: 50.584375 | G11: 25.199314 | H11: 32.138676 | I11: 70.68315 | J11: 76.050023 | K11: 55.24802 | L11: 59.209061 | M11: 58.828027 | N11: 58.837578 | O11: 48.57682 | P11: 115.97087 | Q11: 84.319817 | R11: 83.44358 | S11: 128.44488 | T11: 104.59465 | U11: 46.123762 | V11: 66.413693 | W11: 142.43178 | X11: 81.761757 | Y11: 55.929076 | Z11: 66.560211 | AA11: 69.530115 | AB11: 65.186005 | AC11: 78.496607 | AD11: 70.377339 | AE11: 77.961736 | AF11: 25.895139 | AG11: 90.438927 | AH11: 31.889271
A12: 1993/06 | B12: 00 Estados Unidos Mexicanos | C12: 64.889641 | D12: 107.04492 | E12: 137.95423 | F12: 53.095502 | G12: 26.001286 | H12: 31.676679 | I12: 69.190771 | J12: 74.934497 | K12: 54.088643 | L12: 57.396021 | M12: 58.512591 | N12: 56.595871 | O12: 42.07321 | P12: 117.00489 | Q12: 86.699094 | R12: 82.971441 | S12: 126.42202 | T12: 100.2952 | U12: 43.44326 | V12: 73.834941 | W12: 153.64035 | X12: 81.318807 | Y12: 54.126628 | Z12: 64.564077 | AA12: 66.968807 | AB12: 65.536753 | AC12: 65.890089 | AD12: 76.086124 | AE12: 103.72692 | AF12: 23.6791 | AG12: 91.034314 | AH12: 33.040964
A13: 1993/07 | B13: 00 Estados Unidos Mexicanos | C13: 65.495166 | D13: 106.83809 | E13: 137.35685 | F13: 53.489843 | G13: 26.580011 | H13: 31.38105 | I13: 68.761008 | J13: 74.426791 | K13: 56.228139 | L13: 56.764917 | M13: 59.750249 | N13: 56.357701 | O13: 42.076187 | P13: 106.32986 | Q13: 83.133678 | R13: 82.933361 | S13: 130.51661 | T13: 97.175767 | U13: 44.977981 | V13: 73.024392 | W13: 148.212 | X13: 80.121264 | Y13: 54.181937 | Z13: 64.937822 | AA13: 67.434879 | AB13: 61.326066 | AC13: 84.529011 | AD13: 82.473677 | AE13: 97.995814 | AF13: 23.440331 | AG13: 88.137417 | AH13: 35.43102
A14: 1993/08 | B14: 00 Estados Unidos Mexicanos | C14: 65.637773 | D14: 106.83532 | E14: 137.56185 | F14: 52.898032 | G14: 27.101657 | H14: 30.92036 | I14: 69.534808 | J14: 73.930108 | K14: 57.872844 | L14: 56.810208 | M14: 59.974184 | N14: 56.759682 | O14: 40.981948 | P14: 94.836508 | Q14: 81.971553 | R14: 83.376862 | S14: 127.27282 | T14: 92.80754 | U14: 43.759664 | V14: 77.206098 | W14: 157.87913 | X14: 80.209158 | Y14: 51.200803 | Z14: 64.323537 | AA14: 63.445848 | AB14: 71.558133 | AC14: 90.213942 | AD14: 79.275597 | AE14: 120.00325 | AF14: 21.56152 | AG14: 94.845558 | AH14: 34.938034
A15: 1993/09 | B15: 00 Estados Unidos Mexicanos | C15: 65.512484 | D15: 107.59527 | E15: 138.99254 | F15: 52.400299 | G15: 27.654035 | H15: 30.768484 | I15: 70.541484 | J15: 74.245393 | K15: 62.523989 | L15: 57.759019 | M15: 59.620603 | N15: 57.707769 | O15: 43.33273 | P15: 101.25172 | Q15: 77.021799 | R15: 83.193631 | S15: 123.87747 | T15: 93.151167 | U15: 43.107365 | V15: 75.477804 | W15: 163.73493 | X15: 80.737182 | Y15: 56.270937 | Z15: 65.143517 | AA15: 70.177101 | AB15: 66.755185 | AC15: 70.415114 | AD15: 68.741766 | AE15: 105.05382 | AF15: 22.915854 | AG15: 84.921594 | AH15: 38.369323
A16: 1993/10 | B16: 00 Estados Unidos Mexicanos | C16: 65.772909 | D16: 108.63678 | E16: 140.06229 | F16: 53.293767 | G16: 28.387471 | H16: 30.115482 | I16: 70.806809 | J16: 74.735203 | K16: 63.83413 | L16: 57.197316 | M16: 59.908339 | N16: 57.257624 | O16: 43.659418 | P16: 103.63918 | Q16: 86.606141 | R16: 79.74446 | S16: 141.05957 | T16: 78.681125 | U16: 43.428559 | V16: 74.703641 | W16: 164.62411 | X16: 81.677334 | Y16: 64.754442 | Z16: 65.796034 | AA16: 65.746434 | AB16: 65.89123 | AC16: 94.865197 | AD16: 62.050241 | AE16: 90.261009 | AF16: 22.981858 | AG16: 79.557197 | AH16: 38.032648
A17: 1993/11 | B17: 00 Estados Unidos Mexicanos | C17: 65.810026 | D17: 108.8924 | E17: 140.26391 | F17: 52.937217 | G17: 29.740751 | H17: 29.535901 | I17: 72.75923 | J17: 76.442934 | K17: 68.277141 | L17: 57.645696 | M17: 59.309657 | N17: 56.092058 | O17: 45.783368 | P17: 100.35866 | Q17: 65.694009 | R17: 80.833413 | S17: 128.37659 | T17: 86.016999 | U17: 42.369494 | V17: 72.618676 | W17: 154.66761 | X17: 83.299853 | Y17: 55.112183 | Z17: 65.875154 | AA17: 66.776083 | AB17: 67.053041 | AC17: 70.753737 | AD17: 68.283737 | AE17: 65.83255 | AF17: 22.797105 | AG17: 83.223137 | AH17: 36.801992
A18: 1993/12 | B18: 00 Estados Unidos Mexicanos | C18: 66.828177 | D18: 108.89127 | E18: 140.30418 | F18: 53.494786 | G18: 30.391716 | H18: 29.10059 | I18: 74.806908 | J18: 76.732597 | K18: 72.003171 | L18: 57.589666 | M18: 59.919101 | N18: 57.58651 | O18: 61.14113 | P18: 101.29263 | Q18: 73.924791 | R18: 77.914951 | S18: 128.04001 | T18: 110.68613 | U18: 41.875897 | V18: 74.331414 | W18: 156.11242 | X18: 81.558606 | Y18: 59.679163 | Z18: 64.783387 | AA18: 67.630834 | AB18: 60.486377 | AC18: 76.136316 | AD18: 58.457806 | AE18: 99.509651 | AF18: 23.531083 | AG18: 84.258172 | AH18: 34.280793
... A403: 2026/01 | B403: 00 Estados Unidos Mexicanos | C403: 100.26607 | D403: 88.538752 | E403: 90.922832 | F403: 84.188241 | G403: 84.226612 | H403: 67.218901 | I403: 104.92227 | J403: 104.60379 | K403: 105.23426 | L403: 105.85815 | M403: 104.40091 | N403: 108.54662 | O403: 106.03401 | P403: 72.286366 | Q403: 87.503114 | R403: 67.238564 | S403: 73.925903 | T403: 80.753824 | U403: 96.101415 | V403: 97.789848 | W403: 155.17538 | X403: 99.407875 | Y403: 103.66073 | Z403: 96.944051 | AA403: 91.968931 | AB403: 91.130009 | AC403: 102.37555 | AD403: 120.71998 | AE403: 115.82333 | AF403: 95.761795 | AG403: 83.722627 | AH403: 131.59936
A408: Sources: /f1 INEGI. Series calculadas por métodos econométricos a partir de las cifras generadas por el Sistema de Cuentas Nacionales de México.

Sheet TEND
A1: National Institute of Statistics and Geography (INEGI)
A2: Economic Information Bank
A3: Consult Date: 13/03/2026 07:31:26
A4: Índice base 2018=100
A6: Period | B6: Geographic area | C6: Indicadores económicos de coyuntura > Actividad industrial, base 2018 > Series desestacionalizadas y tendencia-ciclo > Total de la actividad industrial > Tendencia-ciclo > Índice (Índice base 2018=100) Monthly /f1 | D6: Indicadores económicos de coyuntura > Actividad industrial, base 2018 > Series desestacionalizadas y tendencia-ciclo > Minería > Total > Tendencia-ciclo > Índice (Índice base 2018=100) Monthly /f1 | E6: Indicadores económicos de coyuntura > Actividad industrial, base 2018 > Series desestacionalizadas y tendencia-ciclo > Minería > 211 Extracción de petróleo y gas > Tendencia-ciclo > Índice (Índice base 2018=100) Monthly /f1 | F6: Indicadores económicos de coyuntura > Actividad industrial, base 2018 > Series desestacionalizadas y tendencia-ciclo > Minería > 212 Minería de minerales metálicos y no metálicos, excepto petróleo y gas > Tendencia-ciclo > Índice (Índice base 2018=100) Monthly /f1 | G6: Indicadores económicos de coyuntura > Actividad industrial, base 2018 > Series desestacionalizadas y tendencia-ciclo > Minería > 213 Servicios relacionados con la minería > Tendencia-ciclo > Índice (Índice base 2018=100) Monthly /f1 | H6: Indicadores económicos de coyuntura > Actividad industrial, base 2018 > Series desestacionalizadas y tendencia-ciclo > Generación, transmisión y distribución de energía eléctrica, suministro de agua y de gas por ductos al consumidor final > Tendencia-ciclo > Índice (Índice base 2018=100) Monthly /f1 | I6: Indicadores económicos de coyuntura > Actividad industrial, base 2018 > Series desestacionalizadas y tendencia-ciclo > Construcción > Total > Tendencia-ciclo > Índice (Índice base 2018=100) Monthly /f1 | J6: Indicadores económicos de coyuntura > Actividad industrial, base 2018 > Series desestacionalizadas y tendencia-ciclo > Construcción > 236 Edificación > Tendencia-ciclo > Índice (Índice base 2018=100) Monthly /f1 | K6: Indicadores económicos de coyuntura > Actividad industrial, base 2018 > Series desestacionalizadas y tendencia-ciclo > Construcción > 237 Construcción de obras de ingeniería civil > Tendencia-ciclo > Índice (Índice base 2018=100) Monthly /f1 | L6: Indicadores económicos de coyuntura > Actividad industrial, base 2018 > Series desestacionalizadas y tendencia-ciclo > Construcción > 238 Trabajos especializados para la construcción > Tendencia-ciclo > Índice (Índice base 2018=100) Monthly /f1 | M6: Indicadores económicos de coyuntura > Actividad industrial, base 2018 > Series desestacionalizadas y tendencia-ciclo > Industrias manufactureras > Total > Tendencia-ciclo > Índice (Índice base 2018=100) Monthly /f1 | N6: Indicadores económicos de coyuntura > Actividad industrial, base 2018 > Series desestacionalizadas y tendencia-ciclo > Industrias manufactureras > 311 Industria alimentaria > Tendencia-ciclo > Índice (Índice base 2018=100) Monthly /f1 | O6: Indicadores económicos de coyuntura > Actividad industrial, base 2018 > Series desestacionalizadas y tendencia-ciclo > Industrias manufactureras > 312 Industria de las bebidas y del tabaco > Tendencia-ciclo > Índice (Índice base 2018=100) Monthly /f1 | P6: Indicadores económicos de coyuntura > Actividad industrial, base 2018 > Series desestacionalizadas y tendencia-ciclo > Industrias manufactureras > 313 Fabricación de insumos textiles y acabado de textiles > Tendencia-ciclo > Índice (Índice base 2018=100) Monthly /f1 | Q6: Indicadores económicos de coyuntura > Actividad industrial, base 2018 > Series desestacionalizadas y tendencia-ciclo > Industrias manufactureras > 314 Fabricación de productos textiles, excepto prendas de vestir > Tendencia-ciclo > Índice (Índice base 2018=100) Monthly /f1 | R6: Indicadores económicos de coyuntura > Actividad industrial, base 2018 > Series desestacionalizadas y tendencia-ciclo > Industrias manufactureras > 315 Fabricación de prendas de vestir > Tendencia-ciclo > Índice (Índice base 2018=100) Monthly /f1 | S6: Indicadores económicos de coyuntura > Actividad industrial, base 2018 > Series desestacionalizadas y tendencia-ciclo > Industrias manufactureras > 316 Curtido y acabado de cuero y piel, y fabricación de productos de cuero, piel y materiales sucedáneos > Tendencia-ciclo > Índice (Índice base 2018=100) Monthly /f1 | T6: Indicadores económicos de coyuntura > Actividad industrial, base 2018 > Series desestacionalizadas y tendencia-ciclo > Industrias manufactureras > 321 Industria de la madera > Tendencia-ciclo > Índice (Índice base 2018=100) Monthly /f1 | U6: Indicadores económicos de coyuntura > Actividad industrial, base 2018 > Series desestacionalizadas y tendencia-ciclo > Industrias manufactureras > 322 Industria del papel > Tendencia-ciclo > Índice (Índice base 2018=100) Monthly /f1 | V6: Indicadores económicos de coyuntura > Actividad industrial, base 2018 > Series desestacionalizadas y tendencia-ciclo > Industrias manufactureras > 323 Impresión e industrias conexas > Tendencia-ciclo > Índice (Índice base 2018=100) Monthly /f1 | W6: Indicadores económicos de coyuntura > Actividad industrial, base 2018 > Series desestacionalizadas y tendencia-ciclo > Industrias manufactureras > 324 Fabricación de productos derivados del petróleo y del carbón > Tendencia-ciclo > Índice (Índice base 2018=100) Monthly /f1 | X6: Indicadores económicos de coyuntura > Actividad industrial, base 2018 > Series desestacionalizadas y tendencia-ciclo > Industrias manufactureras > 325 Industria química > Tendencia-ciclo > Índice (Índice base 2018=100) Monthly /f1 | Y6: Indicadores económicos de coyuntura > Actividad industrial, base 2018 > Series desestacionalizadas y tendencia-ciclo > Industrias manufactureras > 326 Industria del plástico y del hule > Tendencia-ciclo > Índice (Índice base 2018=100) Monthly /f1 | Z6: Indicadores económicos de coyuntura > Actividad industrial, base 2018 > Series desestacionalizadas y tendencia-ciclo > Industrias manufactureras > 327 Fabricación de productos a base de minerales no metálicos > Tendencia-ciclo > Índice (Índice base 2018=100) Monthly /f1 | AA6: Indicadores económicos de coyuntura > Actividad industrial, base 2018 > Series desestacionalizadas y tendencia-ciclo > Industrias manufactureras > 331 Industrias metálicas básicas > Tendencia-ciclo > Índice (Índice base 2018=100) Monthly /f1 | AB6: Indicadores económicos de coyuntura > Actividad industrial, base 2018 > Series desestacionalizadas y tendencia-ciclo > Industrias manufactureras > 332 Fabricación de productos metálicos > Tendencia-ciclo > Índice (Índice base 2018=100) Monthly /f1 | AC6: Indicadores económicos de coyuntura > Actividad industrial, base 2018 > Series desestacionalizadas y tendencia-ciclo > Industrias manufactureras > 333 Fabricación de maquinaria y equipo > Tendencia-ciclo > Índice (Índice base 2018=100) Monthly /f1 | AD6: Indicadores económicos de coyuntura > Actividad industrial, base 2018 > Series desestacionalizadas y tendencia-ciclo > Industrias manufactureras > 334 Fabricación de equipo de computación, comunicación, medición y de otros equipos, componentes y accesorios electrónicos > Tendencia-ciclo > Índice (Índice base 2018=100) Monthly /f1 | AE6: Indicadores económicos de coyuntura > Actividad industrial, base 2018 > Series desestacionalizadas y tendencia-ciclo > Industrias manufactureras > 335 Fabricación de accesorios, aparatos eléctricos y equipo de generación de energía eléctrica > Tendencia-ciclo > Índice (Índice base 2018=100) Monthly /f1 | AF6: Indicadores económicos de coyuntura > Actividad industrial, base 2018 > Series desestacionalizadas y tendencia-ciclo > Industrias manufactureras > 336 Fabricación de equipo de transporte > Tendencia-ciclo > Índice (Índice base 2018=100) Monthly /f1 | AG6: Indicadores económicos de coyuntura > Actividad industrial, base 2018 > Series desestacionalizadas y tendencia-ciclo > Industrias manufactureras > 337 Fabricación de muebles, colchones y persianas > Tendencia-ciclo > Índice (Índice base 2018=100) Monthly /f1 | AH6: Indicadores económicos de coyuntura > Actividad industrial, base 2018 > Series desestacionalizadas y tendencia-ciclo > Industrias manufactureras > 339 Otras industrias manufactureras > Tendencia-ciclo > Índice (Índice base 2018=100) Monthly /f1
A7: 1993/01 | B7: 00 Estados Unidos Mexicanos | C7: 65.753785 | D7: 104.63136 | E7: 134.93194 | F7: 52.903683 | G7: 26.220813 | H7: 32.398115 | I7: 69.386952 | J7: 74.58321 | K7: 52.583458 | L7: 55.466318 | M7: 58.257212 | N7: 56.69625 | O7: 47.377301 | P7: 106.48411 | Q7: 81.230584 | R7: 84.949402 | S7: 132.26039 | T7: 124.35876 | U7: 45.475749 | V7: 76.381366 | W7: 145.3612 | X7: 80.673173 | Y7: 56.8493 | Z7: 66.742363 | AA7: 69.005214 | AB7: 65.99742 | AC7: 68.951248 | AD7: 56.073654 | AE7: 102.40199 | AF7: 27.056839 | AG7: 90.209283 | AH7: 33.178981
A8: 1993/02 | B8: 00 Estados Unidos Mexicanos | C8: 65.702826 | D8: 105.13176 | E8: 135.60347 | F8: 52.929717 | G8: 26.00097 | H8: 32.350282 | I8: 69.589348 | J8: 74.906052 | K8: 53.138261 | L8: 55.901589 | M8: 58.54595 | N8: 56.697353 | O8: 47.69201 | P8: 107.8477 | Q8: 81.870171 | R8: 84.706284 | S8: 131.16393 | T8: 121.24273 | U8: 45.572174 | V8: 76.184843 | W8: 145.27012 | X8: 81.042499 | Y8: 56.656386 | Z8: 66.844599 | AA8: 69.323449 | AB8: 65.859649 | AC8: 70.00789 | AD8: 59.874969 | AE8: 102.4951 | AF8: 26.936245 | AG8: 90.676712 | AH8: 33.481025
A9: 1993/03 | B9: 00 Estados Unidos Mexicanos | C9: 65.636188 | D9: 105.6387 | E9: 136.28293 | F9: 52.892457 | G9: 25.829882 | H9: 32.254033 | I9: 69.744133 | J9: 75.152865 | K9: 53.712989 | L9: 56.346877 | M9: 58.82572 | N9: 56.689464 | O9: 47.939077 | P9: 109.03596 | Q9: 82.552371 | R9: 84.408528 | S9: 130.07699 | T9: 117.00267 | U9: 45.599261 | V9: 76.050673 | W9: 145.61991 | X9: 81.318423 | Y9: 56.238115 | Z9: 66.789407 | AA9: 69.424191 | AB9: 65.74212 | AC9: 71.701101 | AD9: 64.2197 | AE9: 102.57287 | AF9: 26.560057 | AG9: 91.033678 | AH9: 33.803546
A10: 1993/04 | B10: 00 Estados Unidos Mexicanos | C10: 65.541415 | D10: 106.10951 | E10: 136.91001 | F10: 52.80428 | G10: 25.731925 | H10: 32.122769 | I10: 69.801143 | J10: 75.290862 | K10: 54.267075 | L10: 56.781562 | M10: 59.03971 | N10: 56.675427 | O10: 48.087248 | P10: 109.85071 | Q10: 83.219644 | R10: 84.073028 | S10: 129.12446 | T10: 111.97424 | U10: 45.559139 | V10: 75.836671 | W10: 146.30348 | X10: 81.443586 | Y10: 55.728279 | Z10: 66.554041 | AA10: 69.296378 | AB10: 65.655626 | AC10: 73.835083 | AD10: 68.778779 | AE10: 102.52074 | AF10: 25.986007 | AG10: 91.13847 | AH10: 34.075712
A11: 1993/05 | B11: 00 Estados Unidos Mexicanos | C11: 65.440451 | D11: 106.47665 | E11: 137.3822 | F11: 52.704094 | G11: 25.76258 | H11: 31.950552 | I11: 69.719283 | J11: 75.22629 | K11: 54.7917 | L11: 57.124496 | M11: 59.198419 | N11: 56.66586 | O11: 48.017801 | P11: 109.9398 | Q11: 83.669707 | R11: 83.763474 | S11: 128.36088 | T11: 106.54827 | U11: 45.404687 | V11: 75.611599 | W11: 147.69197 | X11: 81.331108 | Y11: 55.139194 | Z11: 66.107573 | AA11: 68.851406 | AB11: 65.658826 | AC11: 76.451884 | AD11: 73.110609 | AE11: 102.38336 | AF11: 25.181529 | AG11: 90.869826 | AH11: 34.405287
A12: 1993/06 | B12: 00 Estados Unidos Mexicanos | C12: 65.356268 | D12: 106.75505 | E12: 137.71921 | F12: 52.63877 | G12: 26.008891 | H12: 31.721537 | I12: 69.530714 | J12: 74.942674 | K12: 55.473076 | L12: 57.319772 | M12: 59.32192 | N12: 56.693751 | O12: 47.631162 | P12: 109.06707 | Q12: 83.684311 | R12: 83.474334 | S12: 127.79817 | T12: 101.29132 | U12: 45.097848 | V12: 75.35832 | W12: 150.29249 | X12: 81.051888 | Y12: 54.567814 | Z12: 65.575629 | AA12: 68.083935 | AB12: 65.778159 | AC12: 79.005134 | AD12: 76.077279 | AE12: 102.27557 | AF12: 24.239317 | AG12: 90.090258 | AH12: 34.7527
A13: 1993/07 | B13: 00 Estados Unidos Mexicanos | C13: 65.319175 | D13: 107.04396 | E13: 138.04217 | F13: 52.66052 | G13: 26.516721 | H13: 31.41233 | I13: 69.413708 | J13: 74.587495 | K13: 56.539723 | L13: 57.323228 | M13: 59.423945 | N13: 56.78638 | O13: 47.022483 | P13: 107.23501 | Q13: 83.159001 | R13: 83.110723 | S13: 127.38369 | T13: 96.701453 | U13: 44.594384 | V13: 75.091913 | W13: 153.58756 | X13: 80.836289 | Y13: 54.215453 | Z13: 65.106384 | AA13: 67.206449 | AB13: 65.997692 | AC13: 80.617988 | AD13: 76.579294 | AE13: 102.1002 | AF13: 23.359965 | AG13: 88.739992 | AH13: 35.042655
A14: 1993/08 | B14: 00 Estados Unidos Mexicanos | C14: 65.395615 | D14: 107.43142 | E14: 138.45663 | F14: 52.827673 | G14: 27.183254 | H14: 31.022455 | I14: 69.593079 | J14: 74.353388 | K14: 58.282012 | L14: 57.17751 | M14: 59.568465 | N14: 56.950249 | O14: 46.43278 | P14: 104.98476 | Q14: 81.99743 | R14: 82.549047 | S14: 127.20577 | T14: 93.520689 | U14: 43.962601 | V14: 74.786317 | W14: 156.77798 | X14: 80.864975 | Y14: 54.307386 | Z14: 64.851367 | AA14: 66.530609 | AB14: 66.233141 | AC14: 80.821924 | AD14: 74.72963 | AE14: 101.90907 | AF14: 22.755607 | AG14: 87.120015 | AH14: 35.306552
A15: 1993/09 | B15: 00 Estados Unidos Mexicanos | C15: 65.589192 | D15: 107.88726 | E15: 139.00715 | F15: 53.019995 | G15: 27.78559 | H15: 30.573136 | I15: 70.195662 | J15: 74.422947 | K15: 60.853831 | L15: 57.062752 | M15: 59.736523 | N15: 57.143419 | O15: 46.052354 | P15: 103.07891 | Q15: 80.445094 | R15: 81.788445 | S15: 127.18756 | T15: 91.798542 | U15: 43.375033 | V15: 74.482453 | W15: 159.0175 | X15: 81.130161 | Y15: 54.788542 | Z15: 64.894017 | AA15: 66.214398 | AB15: 66.389109 | AC15: 79.645451 | AD15: 71.517595 | AE15: 101.93337 | AF15: 22.534041 | AG15: 85.738487 | AH15: 35.573247
A16: 1993/10 | B16: 00 Estados Unidos Mexicanos | C16: 65.860439 | D16: 108.25622 | E16: 139.54251 | F16: 53.068355 | G16: 28.168435 | H16: 30.083873 | I16: 71.261677 | J16: 74.917096 | K16: 64.368256 | L16: 57.177417 | M16: 59.776637 | N16: 57.294643 | O16: 45.915136 | P16: 101.8358 | Q16: 78.734247 | R16: 80.862181 | S16: 127.43958 | T16: 91.018398 | U16: 42.956193 | V16: 74.19858 | W16: 159.75011 | X16: 81.427814 | Y16: 55.548204 | Z16: 65.192152 | AA16: 66.239515 | AB16: 66.41919 | AC16: 77.465825 | AD16: 67.934583 | AE16: 102.01197 | AF16: 22.620226 | AG16: 84.871591 | AH16: 35.83761
A17: 1993/11 | B17: 00 Estados Unidos Mexicanos | C17: 66.17762 | D17: 108.37236 | E17: 139.86638 | F17: 52.906941 | G17: 28.227973 | H17: 29.591074 | I17: 72.868844 | J17: 75.920625 | K17: 69.013682 | L17: 57.776366 | M17: 59.648402 | N17: 57.326039 | O17: 46.026405 | P17: 101.45521 | Q17: 77.420066 | R17: 79.99581 | S17: 128.01301 | T17: 91.168576 | U17: 42.807389 | V17: 73.981303 | W17: 159.26885 | X17: 81.632182 | Y17: 56.487595 | Z17: 65.606268 | AA17: 66.518147 | AB17: 66.487971 | AC17: 74.905105 | AD17: 65.329891 | AE17: 101.87795 | AF17: 22.930665 | AG17: 84.630173 | AH17: 36.081467
A18: 1993/12 | B18: 00 Estados Unidos Mexicanos | C18: 66.545876 | D18: 108.1996 | E18: 139.8286 | F18: 52.711167 | G18: 28.006331 | H18: 29.120517 | I18: 74.959201 | J18: 77.422033 | K18: 74.647589 | L18: 58.917465 | M18: 59.43491 | N18: 57.225115 | O18: 46.271867 | P18: 101.98919 | Q18: 76.903539 | R18: 79.591104 | S18: 128.6281 | T18: 92.188151 | U18: 42.987016 | V18: 73.855835 | W18: 158.33072 | X18: 81.72094 | Y18: 57.503001 | Z18: 66.050319 | AA18: 66.923175 | AB18: 66.75456 | AC18: 72.737399 | AD18: 64.517618 | AE18: 101.48995 | AF18: 23.375687 | AG18: 84.967376 | AH18: 36.293836
... A403: 2026/01 | B403: 00 Estados Unidos Mexicanos | C403: 100.70596 | D403: 89.219017 | E403: 90.850315 | F403: 85.556665 | G403: 85.11928 | H403: 67.826936 | I403: 105.61406 | J403: 106.23285 | K403: 104.51099 | L403: 104.64392 | M403: 104.83204 | N403: 108.89622 | O403: 105.0606 | P403: 73.988331 | Q403: 88.498658 | R403: 67.714357 | S403: 73.667115 | T403: 80.085546 | U403: 96.402368 | V403: 94.854619 | W403: 165.69878 | X403: 99.719445 | Y403: 103.78448 | Z403: 97.383911 | AA403: 93.614008 | AB403: 91.402655 | AC403: 102.9461 | AD403: 121.11329 | AE403: 117.43339 | AF403: 96.157743 | AG403: 83.186505 | AH403: 134.00432
A408: Sources: /f1 INEGI. Series calculadas por métodos econométricos a partir de las cifras generadas por el Sistema de Cuentas Nacionales de México.

Sheet PIB18
B1: ACTIVIDAD INDUSTRIAL | C1: Industria Minera | D1: Extracción de petróleo y gas | E1: Minería de minerales metálicos y no metálicos excepto petróleo y gas, y servicios relacionados | F1: Servicios relacionados con la minería | G1: Electricidad, agua y suministro de gas por ductos al consumidor fina | H1: Generación, transmisión y suministro de energía eléctrica | I1: Construcción | J1: Edificación | K1: Construcción de obras de ingeniería civil u obra pesada | L1: Trabajos especializados para la construcción | M1: Total industrias manufactureras | N1: Industria alimentaria | O1: Industria de las bebidas y del tabaco | P1: Fabricación de insumos textiles | Q1: Confección de productos textiles, excepto prendas de vestir | R1: Fabricación de prendas de vestir | S1: Fabricación de productos de cuero, piel y materiales sucedáneos, excepto prendas de vestir | T1: Industria de la madera | U1: Industria del papel | V1: Impresión e industrias conexas | W1: Fabricación de productos derivados del petróleo y del carbón | X1: Industria química | Y1: Industria del plástico y del hule | Z1: Fabricación de productos a base de minerales no metálicos | AA1: Industrias metálicas básicas | AB1: Fabricación de productos metálicos | AC1: Fabricación de maquinaria y equipo | AD1: Fabricación de equipo de computación, comunicación, medición y otros equipos, componentes y accesorios electrónicos | AE1: Fabricación de equipo de generación eléctrica y aparatos y accesorios eléctricos | AF1: Fabricación de equipo de transporte | AG1: Fabricación de muebles y productos relacionados | AH1: Otras industrias manufactureras
B2: Indicadores económicos de coyuntura > Actividad industrial, base 2018 > Series Originales > Índice de volumen físico > Total de la actividad industrial (Índice base 2018=100) Monthly /f1 | C2: Indicadores económicos de coyuntura > Actividad industrial, base 2018 > Series Originales > Índice de volumen físico > 21 Minería > Total minería (Índice base 2018=100) Monthly /f1 | D2: Indicadores económicos de coyuntura > Actividad industrial, base 2018 > Series Originales > Índice de volumen físico > 21 Minería > 211 Extracción de petróleo y gas (Índice base 2018=100) Monthly /f1 | E2: Indicadores económicos de coyuntura > Actividad industrial, base 2018 > Series Originales > Índice de volumen físico > 21 Minería > 212 Minería de minerales metálicos y no metálicos excepto petróleo y gas (Índice base 2018=100) Monthly /f1 | F2: Indicadores económicos de coyuntura > Actividad industrial, base 2018 > Series Originales > Índice de volumen físico > 21 Minería > 213 Servicios relacionados con la minería (Índice base 2018=100) Monthly /f1 | G2: Indicadores económicos de coyuntura > Actividad industrial, base 2018 > Series Originales > Índice de volumen físico > 22 Generación, transmisión y distribución de energía eléctrica, suministro de agua y de gas por ductos al consumidor final > Total generación, transmisión y distribución de energía eléctrica, suministro de agua y de gas por ductos al consumidor final (Índice base 2018=100) Monthly /f1 | H2: Indicadores económicos de coyuntura > Actividad industrial, base 2018 > Series Originales > Índice de volumen físico > 22 Generación, transmisión y distribución de energía eléctrica, suministro de agua y de gas por ductos al consumidor final > 221 Generación, transmisión, distribución y comercialización de energía eléctrica, suministro de agua y de gas natural por ductos al consumidor final (Índice base 2018=100) Monthly /f1 | I2: Indicadores económicos de coyuntura > Actividad industrial, base 2018 > Series Originales > Índice de volumen físico > 23 Construcción > Total construcción (Índice base 2018=100) Monthly /f1 | J2: Indicadores económicos de coyuntura > Actividad industrial, base 2018 > Series Originales > Índice de volumen físico > 23 Construcción > 236 Edificación (Índice base 2018=100) Monthly /f1 | K2: Indicadores económicos de coyuntura > Actividad industrial, base 2018 > Series Originales > Índice de volumen físico > 23 Construcción > 237 Construcción de obras de ingeniería civil (Índice base 2018=100) Monthly /f1 | L2: Indicadores económicos de coyuntura > Actividad industrial, base 2018 > Series Originales > Índice de volumen físico > 23 Construcción > 238 Trabajos especializados para la construcción (Índice base 2018=100) Monthly /f1 | M2: Indicadores económicos de coyuntura > Actividad industrial, base 2018 > Series Originales > Índice de volumen físico > 31-33 Industrias manufactureras > Total industrias manufactureras (Índice base 2018=100) Monthly /f1 | N2: Indicadores económicos de coyuntura > Actividad industrial, base 2018 > Series Originales > Índice de volumen físico > 31-33 Industrias manufactureras > 311 Industria alimentaria > Total subsector 311 (Índice base 2018=100) Monthly /f1 | O2: Indicadores económicos de coyuntura > Actividad industrial, base 2018 > Series Originales > Índice de volumen físico > 31-33 Industrias manufactureras > 312 Industria de las bebidas y del tabaco > Total subsector 312 (Índice base 2018=100) Monthly /f1 | P2: Indicadores económicos de coyuntura > Actividad industrial, base 2018 > Series Originales > Índice de volumen físico > 31-33 Industrias manufactureras > 313 Fabricación de insumos textiles y acabado de textiles > Total subsector 313 (Índice base 2018=100) Monthly /f1 | Q2: Indicadores económicos de coyuntura > Actividad industrial, base 2018 > Series Originales > Índice de volumen físico > 31-33 Industrias manufactureras > 314 Fabricación de productos textiles, excepto prendas de vestir > Total subsector 314 (Índice base 2018=100) Monthly /f1 | R2: Indicadores económicos de coyuntura > Actividad industrial, base 2018 > Series Originales > Índice de volumen físico > 31-33 Industrias manufactureras > 315 Fabricación de prendas de vestir > Total subsector 315 (Índice base 2018=100) Monthly /f1 | S2: Indicadores económicos de coyuntura > Actividad industrial, base 2018 > Series Originales > Índice de volumen físico > 31-33 Industrias manufactureras > 316 Curtido y acabado de cuero y piel, y fabricación de productos de cuero, piel y materiales sucedáneos > Total subsector 316 (Índice base 2018=100) Monthly /f1 | T2: Indicadores económicos de coyuntura > Actividad industrial, base 2018 > Series Originales > Índice de volumen físico > 31-33 Industrias manufactureras > 321 Industria de la madera > Total subsector 321 (Índice base 2018=100) Monthly /f1 | U2: Indicadores económicos de coyuntura > Actividad industrial, base 2018 > Series Originales > Índice de volumen físico > 31-33 Industrias manufactureras > 322 Industria del papel > Total subsector 322 (Índice base 2018=100) Monthly /f1 | V2: Indicadores económicos de coyuntura > Actividad industrial, base 2018 > Series Originales > Índice de volumen físico > 31-33 Industrias manufactureras > 323 Impresión e industrias conexas > Total subsector 323 (Índice base 2018=100) Monthly /f1 | W2: Indicadores económicos de coyuntura > Actividad industrial, base 2018 > Series Originales > Índice de volumen físico > 31-33 Industrias manufactureras > 324 Fabricación de productos derivados del petróleo y del carbón > Total subsector 324 (Índice base 2018=100) Monthly /f1 | X2: Indicadores económicos de coyuntura > Actividad industrial, base 2018 > Series Originales > Índice de volumen físico > 31-33 Industrias manufactureras > 325 Industria química > Total subsector 325 (Índice base 2018=100) Monthly /f1 | Y2: Indicadores económicos de coyuntura > Actividad industrial, base 2018 > Series Originales > Índice de volumen físico > 31-33 Industrias manufactureras > 326 Industria del plástico y del hule > Total subsector 326 (Índice base 2018=100) Monthly /f1 | Z2: Indicadores económicos de coyuntura > Actividad industrial, base 2018 > Series Originales > Índice de volumen físico > 31-33 Industrias manufactureras > 327 Fabricación de productos a base de minerales no metálicos > Total subsector 327 (Índice base 2018=100) Monthly /f1 | AA2: Indicadores económicos de coyuntura > Actividad industrial, base 2018 > Series Originales > Índice de volumen físico > 31-33 Industrias manufactureras > 331 Industrias metálicas básicas > Total subsector 331 (Índice base 2018=100) Monthly /f1 | AB2: Indicadores económicos de coyuntura > Actividad industrial, base 2018 > Series Originales > Índice de volumen físico > 31-33 Industrias manufactureras > 332 Fabricación de productos metálicos > Total subsector 332 (Índice base 2018=100) Monthly /f1 | AC2: Indicadores económicos de coyuntura > Actividad industrial, base 2018 > Series Originales > Índice de volumen físico > 31-33 Industrias manufactureras > 333 Fabricación de maquinaria y equipo > Total subsector 333 (Índice base 2018=100) Monthly /f1 | AD2: Indicadores económicos de coyuntura > Actividad industrial, base 2018 > Series Originales > Índice de volumen físico > 31-33 Industrias manufactureras > 334 Fabricación de equipo de computación, comunicación, medición y de otros equipos, componentes y accesorios electrónicos > Total subsector 334 (Índice base 2018=100) Monthly /f1 | AE2: Indicadores económicos de coyuntura > Actividad industrial, base 2018 > Series Originales > Índice de volumen físico > 31-33 Industrias manufactureras > 335 Fabricación de accesorios, aparatos eléctricos y equipo de generación de energía eléctrica > Total subsector 335 (Índice base 2018=100) Monthly /f1 | AF2: Indicadores económicos de coyuntura > Actividad industrial, base 2018 > Series Originales > Índice de volumen físico > 31-33 Industrias manufactureras > 336 Fabricación de equipo de transporte > Total subsector 336 (Índice base 2018=100) Monthly /f1 | AG2: Indicadores económicos de coyuntura > Actividad industrial, base 2018 > Series Originales > Índice de volumen físico > 31-33 Industrias manufactureras > 337 Fabricación de muebles, colchones y persianas > Total subsector 337 (Índice base 2018=100) Monthly /f1 | AH2: Indicadores económicos de coyuntura > Actividad industrial, base 2018 > Series Originales > Índice de volumen físico > 31-33 Industrias manufactureras > 339 Otras industrias manufactureras > Total subsector 339 (Índice base 2018=100) Monthly /f1
